Workbook

Sheet raw
B1: 1988Q1 | C1: 1988Q2 | D1: 1988Q3 | E1: 1988Q4 | F1: 1989Q1 | G1: 1989Q2 | H1: 1989Q3 | I1: 1989Q4 | J1: 1990Q1 | K1: 1990Q2 | L1: 1990Q3 | M1: 1990Q4 | N1: 1991Q1 | O1: 1991Q2 | P1: 1991Q3 | Q1: 1991Q4 | R1: 1992Q1 | S1: 1992Q2 | T1: 1992Q3 | U1: 1992Q4 | V1: 1993Q1 | W1: 1993Q2 | X1: 1993Q3 | Y1: 1993Q4 | Z1: 1994Q1 | AA1: 1994Q2 | AB1: 1994Q3 | AC1: 1994Q4 | AD1: 1995Q1 | AE1: 1995Q2 | AF1: 1995Q3 | AG1: 1995Q4 | AH1: 1996Q1 | AI1: 1996Q2 | AJ1: 1996Q3 | AK1: 1996Q4 | AL1: 1997Q1 | AM1: 1997Q2 | AN1: 1997Q3 | AO1: 1997Q4 | AP1: 1998Q1 | AQ1: 1998Q2 | AR1: 1998Q3 | AS1: 1998Q4 | AT1: 1999Q1 | AU1: 1999Q2 | AV1: 1999Q3 | AW1: 1999Q4 | AX1: 2000Q1 | AY1: 2000Q2 | AZ1: 2000Q3 | BA1: 2000Q4 | BB1: 2001Q1 | BC1: 2001Q2 | BD1: 2001Q3 | BE1: 2001Q4 | BF1: 2002Q1 | BG1: 2002Q2 | BH1: 2002Q3 | BI1: 2002Q4 | BJ1: 2003Q1 | BK1: 2003Q2 | BL1: 2003Q3 | BM1: 2003Q4 | BN1: 2004Q1 | BO1: 2004Q2 | BP1: 2004Q3 | BQ1: 2004Q4 | BR1: 2005Q1 | BS1: 2005Q2 | BT1: 2005Q3 | BU1: 2005Q4 | BV1: 2006Q1 | BW1: 2006Q2 | BX1: 2006Q3 | BY1: 2006Q4 | BZ1: 2007Q1 | CA1: 2007Q2 | CB1: 2007Q3 | CC1: 2007Q4 | CD1: 2008Q1 | CE1: 2008Q2 | CF1: 2008Q3 | CG1: 2008Q4 | CH1: 2009Q1 | CI1: 2009Q2 | CJ1: 2009Q3 | CK1: 2009Q4 | CL1: 2010Q1 | CM1: 2010Q2 | CN1: 2010Q3 | CO1: 2010Q4 | CP1: 2011Q1 | CQ1: 2011Q2 | CR1: 2011Q3 | CS1: 2011Q4 | CT1: 2012Q1 | CU1: 2012Q2 | CV1: 2012Q3 | CW1: 2012Q4 | CX1: 2013Q1 | CY1: 2013Q2 | CZ1: 2013Q3 | DA1: 2013Q4 | DB1: 2014Q1 | DC1: 2014Q2 | DD1: 2014Q3 | DE1: 2014Q4 | DF1: 2015Q1 | DG1: 2015Q2 | DH1: 2015Q3 | DI1: 2015Q4 | DJ1: 2016Q1 | DK1: 2016Q2 | DL1: 2016Q3 | DM1: 2016Q4 | DN1: 2017Q1 | DO1: 2017Q2 | DP1: 2017Q3 | DQ1: 2017Q4 | DR1: 2018Q1 | DS1: 2018Q2 | DT1: 2018Q3 | DU1: 2018Q4 | DV1: 2019Q1 | DW1: 2019Q2 | DX1: 2019Q3 | DY1: 2019Q4 | DZ1: 2020Q1 | EA1: 2020Q2 | EB1: 2020Q3 | EC1: 2020Q4 | ED1: 2021Q1 | EE1: 2021Q2 | EF1: 2021Q3
A2: 26023 | B2: NaN | C2: NaN | D2: NaN | E2: NaN | F2: NaN | G2: NaN | H2: NaN | I2: NaN | J2: NaN | K2: NaN | L2: NaN | M2: NaN | N2: NaN | O2: NaN | P2: NaN | Q2: NaN | R2: NaN | S2: NaN | T2: NaN | U2: NaN | V2: NaN | W2: NaN | X2: NaN | Y2: NaN | Z2: NaN | AA2: NaN | AB2: NaN | AC2: NaN | AD2: NaN | AE2: NaN | AF2: NaN | AG2: NaN | AH2: NaN | AI2: NaN | AJ2: NaN | AK2: NaN | AL2: NaN | AM2: NaN | AN2: NaN | AO2: NaN | AP2: NaN | AQ2: NaN | AR2: NaN | AS2: NaN | AT2: NaN | AU2: NaN | AV2: NaN | AW2: NaN | AX2: NaN | AY2: NaN | AZ2: NaN | BA2: NaN | BB2: NaN | BC2: NaN | BD2: NaN | BE2: NaN | BF2: NaN | BG2: NaN | BH2: NaN | BI2: NaN | BJ2: NaN | BK2: NaN | BL2: NaN | BM2: NaN | BN2: NaN | BO2: NaN | BP2: NaN | BQ2: NaN | BR2: NaN | BS2: NaN | BT2: NaN | BU2: NaN | BV2: NaN | BW2: NaN | BX2: NaN | BY2: NaN | BZ2: NaN | CA2: NaN | CB2: NaN | CC2: NaN | CD2: NaN | CE2: NaN | CF2: NaN | CG2: NaN | CH2: NaN | CI2: NaN | CJ2: NaN | CK2: NaN | CL2: NaN | CM2: NaN | CN2: NaN | CO2: NaN | CP2: NaN | CQ2: NaN | CR2: NaN | CS2: NaN | CT2: NaN | CU2: NaN | CV2: NaN | CW2: NaN | CX2: NaN | CY2: NaN | CZ2: NaN | DA2: NaN | DB2: NaN | DC2: NaN | DD2: NaN | DE2: NaN | DF2: NaN | DG2: NaN | DH2: NaN | DI2: NaN | DJ2: NaN | DK2: NaN | DL2: NaN | DM2: NaN | DN2: NaN | DO2: NaN | DP2: 0.83 | DQ2: 0.85 | DR2: 0.85 | DS2: 0.86 | DT2: 0.87 | DU2: 0.87 | DV2: 0.88 | DW2: 0.89 | DX2: 0.9 | DY2: 0.91 | DZ2: 0.92 | EA2: 0.92 | EB2: 0.97583 | EC2: 0.9864 | ED2: 0.99516 | EE2: 1.00454 | EF2: 1.00582
A3: 26114 | B3: NaN | C3: NaN | D3: NaN | E3: NaN | F3: NaN | G3: NaN | H3: NaN | I3: NaN | J3: NaN | K3: NaN | L3: NaN | M3: NaN | N3: NaN | O3: NaN | P3: NaN | Q3: NaN | R3: NaN | S3: NaN | T3: NaN | U3: NaN | V3: NaN | W3: NaN | X3: NaN | Y3: NaN | Z3: NaN | AA3: NaN | AB3: NaN | AC3: NaN | AD3: NaN | AE3: NaN | AF3: NaN | AG3: NaN | AH3: NaN | AI3: NaN | AJ3: NaN | AK3: NaN | AL3: NaN | AM3: NaN | AN3: NaN | AO3: NaN | AP3: NaN | AQ3: NaN | AR3: NaN | AS3: NaN | AT3: NaN | AU3: NaN | AV3: NaN | AW3: NaN | AX3: NaN | AY3: NaN | AZ3: NaN | BA3: NaN | BB3: NaN | BC3: NaN | BD3: NaN | BE3: NaN | BF3: NaN | BG3: NaN | BH3: NaN | BI3: NaN | BJ3: NaN | BK3: NaN | BL3: NaN | BM3: NaN | BN3: NaN | BO3: NaN | BP3: NaN | BQ3: NaN | BR3: NaN | BS3: NaN | BT3: NaN | BU3: NaN | BV3: NaN | BW3: NaN | BX3: NaN | BY3: NaN | BZ3: NaN | CA3: NaN | CB3: NaN | CC3: NaN | CD3: NaN | CE3: NaN | CF3: NaN | CG3: NaN | CH3: NaN | CI3: NaN | CJ3: NaN | CK3: NaN | CL3: NaN | CM3: NaN | CN3: NaN | CO3: NaN | CP3: NaN | CQ3: NaN | CR3: NaN | CS3: NaN | CT3: NaN | CU3: NaN | CV3: NaN | CW3: NaN | CX3: NaN | CY3: NaN | CZ3: NaN | DA3: NaN | DB3: NaN | DC3: NaN | DD3: NaN | DE3: NaN | DF3: NaN | DG3: NaN | DH3: NaN | DI3: NaN | DJ3: NaN | DK3: NaN | DL3: NaN | DM3: NaN | DN3: NaN | DO3: NaN | DP3: 0.74 | DQ3: 0.77 | DR3: 0.78 | DS3: 0.79 | DT3: 0.8 | DU3: 0.81 | DV3: 0.82 | DW3: 0.83 | DX3: 0.84 | DY3: 0.86 | DZ3: 0.86 | EA3: 0.88 | EB3: 0.9238 | EC3: 0.93449 | ED3: 0.94244 | EE3: 0.95533 | EF3: 0.9555
A4: 26206 | B4: NaN | C4: NaN | D4: NaN | E4: NaN | F4: NaN | G4: NaN | H4: NaN | I4: NaN | J4: NaN | K4: NaN | L4: NaN | M4: NaN | N4: NaN | O4: NaN | P4: NaN | Q4: NaN | R4: NaN | S4: NaN | T4: NaN | U4: NaN | V4: NaN | W4: NaN | X4: NaN | Y4: NaN | Z4: NaN | AA4: NaN | AB4: NaN | AC4: NaN | AD4: NaN | AE4: NaN | AF4: NaN | AG4: NaN | AH4: NaN | AI4: NaN | AJ4: NaN | AK4: NaN | AL4: NaN | AM4: NaN | AN4: NaN | AO4: NaN | AP4: NaN | AQ4: NaN | AR4: NaN | AS4: NaN | AT4: NaN | AU4: NaN | AV4: NaN | AW4: NaN | AX4: NaN | AY4: NaN | AZ4: NaN | BA4: NaN | BB4: NaN | BC4: NaN | BD4: NaN | BE4: NaN | BF4: NaN | BG4: NaN | BH4: NaN | BI4: NaN | BJ4: NaN | BK4: NaN | BL4: NaN | BM4: NaN | BN4: NaN | BO4: NaN | BP4: NaN | BQ4: NaN | BR4: NaN | BS4: NaN | BT4: NaN | BU4: NaN | BV4: NaN | BW4: NaN | BX4: NaN | BY4: NaN | BZ4: NaN | CA4: NaN | CB4: NaN | CC4: NaN | CD4: NaN | CE4: NaN | CF4: NaN | CG4: NaN | CH4: NaN | CI4: NaN | CJ4: NaN | CK4: NaN | CL4: NaN | CM4: NaN | CN4: NaN | CO4: NaN | CP4: NaN | CQ4: NaN | CR4: NaN | CS4: NaN | CT4: NaN | CU4: NaN | CV4: NaN | CW4: NaN | CX4: NaN | CY4: NaN | CZ4: NaN | DA4: NaN | DB4: NaN | DC4: NaN | DD4: NaN | DE4: NaN | DF4: NaN | DG4: NaN | DH4: NaN | DI4: NaN | DJ4: NaN | DK4: NaN | DL4: NaN | DM4: NaN | DN4: NaN | DO4: NaN | DP4: 1.89 | DQ4: 1.81 | DR4: 1.79 | DS4: 1.78 | DT4: 1.78 | DU4: 1.77 | DV4: 1.78 | DW4: 1.79 | DX4: 1.77 | DY4: 1.77 | DZ4: 1.79 | EA4: 1.82 | EB4: 2.13122 | EC4: 2.13726 | ED4: 2.13964 | EE4: 2.12659 | EF4: 2.13064
A5: 26298 | B5: NaN | C5: NaN | D5: NaN | E5: NaN | F5: NaN | G5: NaN | H5: NaN | I5: NaN | J5: NaN | K5: NaN | L5: NaN | M5: NaN | N5: NaN | O5: NaN | P5: NaN | Q5: NaN | R5: NaN | S5: NaN | T5: NaN | U5: NaN | V5: NaN | W5: NaN | X5: NaN | Y5: NaN | Z5: NaN | AA5: NaN | AB5: NaN | AC5: NaN | AD5: NaN | AE5: NaN | AF5: NaN | AG5: NaN | AH5: NaN | AI5: NaN | AJ5: NaN | AK5: NaN | AL5: NaN | AM5: NaN | AN5: NaN | AO5: NaN | AP5: NaN | AQ5: NaN | AR5: NaN | AS5: NaN | AT5: NaN | AU5: NaN | AV5: NaN | AW5: NaN | AX5: NaN | AY5: NaN | AZ5: NaN | BA5: NaN | BB5: NaN | BC5: NaN | BD5: NaN | BE5: NaN | BF5: NaN | BG5: NaN | BH5: NaN | BI5: NaN | BJ5: NaN | BK5: NaN | BL5: NaN | BM5: NaN | BN5: NaN | BO5: NaN | BP5: NaN | BQ5: NaN | BR5: NaN | BS5: NaN | BT5: NaN | BU5: NaN | BV5: NaN | BW5: NaN | BX5: NaN | BY5: NaN | BZ5: NaN | CA5: NaN | CB5: NaN | CC5: NaN | CD5: NaN | CE5: NaN | CF5: NaN | CG5: NaN | CH5: NaN | CI5: NaN | CJ5: NaN | CK5: NaN | CL5: NaN | CM5: NaN | CN5: NaN | CO5: NaN | CP5: NaN | CQ5: NaN | CR5: NaN | CS5: NaN | CT5: NaN | CU5: NaN | CV5: NaN | CW5: NaN | CX5: NaN | CY5: NaN | CZ5: NaN | DA5: NaN | DB5: NaN | DC5: NaN | DD5: NaN | DE5: NaN | DF5: NaN | DG5: NaN | DH5: NaN | DI5: NaN | DJ5: NaN | DK5: NaN | DL5: NaN | DM5: NaN | DN5: NaN | DO5: NaN | DP5: 1.08 | DQ5: 1.04 | DR5: 1.03 | DS5: 1.02 | DT5: 1.02 | DU5: 1.03 | DV5: 1.03 | DW5: 1.04 | DX5: 1.03 | DY5: 1.04 | DZ5: 1.05 | EA5: 1.08 | EB5: 1.25 | EC5: 1.25578 | ED5: 1.25776 | EE5: 1.24961 | EF5: 1.25335
A6: 26389 | B6: NaN | C6: NaN | D6: NaN | E6: NaN | F6: NaN | G6: NaN | H6: NaN | I6: NaN | J6: NaN | K6: NaN | L6: NaN | M6: NaN | N6: NaN | O6: NaN | P6: NaN | Q6: NaN | R6: NaN | S6: NaN | T6: NaN | U6: NaN | V6: NaN | W6: NaN | X6: NaN | Y6: NaN | Z6: NaN | AA6: NaN | AB6: NaN | AC6: NaN | AD6: NaN | AE6: NaN | AF6: NaN | AG6: NaN | AH6: NaN | AI6: NaN | AJ6: NaN | AK6: NaN | AL6: NaN | AM6: NaN | AN6: NaN | AO6: NaN | AP6: NaN | AQ6: NaN | AR6: NaN | AS6: NaN | AT6: NaN | AU6: NaN | AV6: NaN | AW6: NaN | AX6: NaN | AY6: NaN | AZ6: NaN | BA6: NaN | BB6: NaN | BC6: NaN | BD6: NaN | BE6: NaN | BF6: NaN | BG6: NaN | BH6: NaN | BI6: NaN | BJ6: NaN | BK6: NaN | BL6: NaN | BM6: NaN | BN6: NaN | BO6: NaN | BP6: NaN | BQ6: NaN | BR6: NaN | BS6: NaN | BT6: NaN | BU6: NaN | BV6: NaN | BW6: NaN | BX6: NaN | BY6: NaN | BZ6: NaN | CA6: NaN | CB6: NaN | CC6: NaN | CD6: NaN | CE6: NaN | CF6: NaN | CG6: NaN | CH6: NaN | CI6: NaN | CJ6: NaN | CK6: NaN | CL6: NaN | CM6: NaN | CN6: NaN | CO6: NaN | CP6: NaN | CQ6: NaN | CR6: NaN | CS6: NaN | CT6: NaN | CU6: NaN | CV6: NaN | CW6: NaN | CX6: NaN | CY6: NaN | CZ6: NaN | DA6: NaN | DB6: NaN | DC6: NaN | DD6: NaN | DE6: NaN | DF6: NaN | DG6: NaN | DH6: NaN | DI6: NaN | DJ6: NaN | DK6: NaN | DL6: NaN | DM6: NaN | DN6: NaN | DO6: NaN | DP6: 0.2 | DQ6: 0.16 | DR6: 0.15 | DS6: 0.15 | DT6: 0.15 | DU6: 0.15 | DV6: 0.15 | DW6: 0.16 | DX6: 0.16 | DY6: 0.16 | DZ6: 0.17 | EA6: 0.2 | EB6: 0.32121 | EC6: 0.32668 | ED6: 0.32995 | EE6: 0.32625 | EF6: 0.32904
A7: 26480 | B7: NaN | C7: NaN | D7: NaN | E7: NaN | F7: NaN | G7: NaN | H7: NaN | I7: NaN | J7: NaN | K7: NaN | L7: NaN | M7: NaN | N7: NaN | O7: NaN | P7: NaN | Q7: NaN | R7: NaN | S7: NaN | T7: NaN | U7: NaN | V7: NaN | W7: NaN | X7: NaN | Y7: NaN | Z7: NaN | AA7: NaN | AB7: NaN | AC7: NaN | AD7: NaN | AE7: NaN | AF7: NaN | AG7: NaN | AH7: NaN | AI7: NaN | AJ7: NaN | AK7: NaN | AL7: NaN | AM7: NaN | AN7: NaN | AO7: NaN | AP7: NaN | AQ7: NaN | AR7: NaN | AS7: NaN | AT7: NaN | AU7: NaN | AV7: NaN | AW7: NaN | AX7: NaN | AY7: NaN | AZ7: NaN | BA7: NaN | BB7: NaN | BC7: NaN | BD7: NaN | BE7: NaN | BF7: NaN | BG7: NaN | BH7: NaN | BI7: NaN | BJ7: NaN | BK7: NaN | BL7: NaN | BM7: NaN | BN7: NaN | BO7: NaN | BP7: NaN | BQ7: NaN | BR7: NaN | BS7: NaN | BT7: NaN | BU7: NaN | BV7: NaN | BW7: NaN | BX7: NaN | BY7: NaN | BZ7: NaN | CA7: NaN | CB7: NaN | CC7: NaN | CD7: NaN | CE7: NaN | CF7: NaN | CG7: NaN | CH7: NaN | CI7: NaN | CJ7: NaN | CK7: NaN | CL7: NaN | CM7: NaN | CN7: NaN | CO7: NaN | CP7: NaN | CQ7: NaN | CR7: NaN | CS7: NaN | CT7: NaN | CU7: NaN | CV7: NaN | CW7: NaN | CX7: NaN | CY7: NaN | CZ7: NaN | DA7: NaN | DB7: NaN | DC7: NaN | DD7: NaN | DE7: NaN | DF7: NaN | DG7: NaN | DH7: NaN | DI7: NaN | DJ7: NaN | DK7: NaN | DL7: NaN | DM7: NaN | DN7: NaN | DO7: NaN | DP7: 0.05 | DQ7: 0.04 | DR7: 0.03 | DS7: 0.03 | DT7: 0.03 | DU7: 0.03 | DV7: 0.04 | DW7: 0.05 | DX7: 0.05 | DY7: 0.05 | DZ7: 0.06 | EA7: 0.07 | EB7: 0.1642 | EC7: 0.16979 | ED7: 0.17478 | EE7: 0.17579 | EF7: 0.17807
A8: 26572 | B8: NaN | C8: NaN | D8: NaN | E8: NaN | F8: NaN | G8: NaN | H8: NaN | I8: NaN | J8: NaN | K8: NaN | L8: NaN | M8: NaN | N8: NaN | O8: NaN | P8: NaN | Q8: NaN | R8: NaN | S8: NaN | T8: NaN | U8: NaN | V8: NaN | W8: NaN | X8: NaN | Y8: NaN | Z8: NaN | AA8: NaN | AB8: NaN | AC8: NaN | AD8: NaN | AE8: NaN | AF8: NaN | AG8: NaN | AH8: NaN | AI8: NaN | AJ8: NaN | AK8: NaN | AL8: NaN | AM8: NaN | AN8: NaN | AO8: NaN | AP8: NaN | AQ8: NaN | AR8: NaN | AS8: NaN | AT8: NaN | AU8: NaN | AV8: NaN | AW8: NaN | AX8: NaN | AY8: NaN | AZ8: NaN | BA8: NaN | BB8: NaN | BC8: NaN | BD8: NaN | BE8: NaN | BF8: NaN | BG8: NaN | BH8: NaN | BI8: NaN | BJ8: NaN | BK8: NaN | BL8: NaN | BM8: NaN | BN8: NaN | BO8: NaN | BP8: NaN | BQ8: NaN | BR8: NaN | BS8: NaN | BT8: NaN | BU8: NaN | BV8: NaN | BW8: NaN | BX8: NaN | BY8: NaN | BZ8: NaN | CA8: NaN | CB8: NaN | CC8: NaN | CD8: NaN | CE8: NaN | CF8: NaN | CG8: NaN | CH8: NaN | CI8: NaN | CJ8: NaN | CK8: NaN | CL8: NaN | CM8: NaN | CN8: NaN | CO8: NaN | CP8: NaN | CQ8: NaN | CR8: NaN | CS8: NaN | CT8: NaN | CU8: NaN | CV8: NaN | CW8: NaN | CX8: NaN | CY8: NaN | CZ8: NaN | DA8: NaN | DB8: NaN | DC8: NaN | DD8: NaN | DE8: NaN | DF8: NaN | DG8: NaN | DH8: NaN | DI8: NaN | DJ8: NaN | DK8: NaN | DL8: NaN | DM8: NaN | DN8: NaN | DO8: NaN | DP8: -0.32 | DQ8: -0.32 | DR8: -0.32 | DS8: -0.32 | DT8: -0.32 | DU8: -0.32 | DV8: -0.31 | DW8: -0.31 | DX8: -0.3 | DY8: -0.3 | DZ8: -0.29 | EA8: -0.28 | EB8: -0.20961 | EC8: -0.20292 | ED8: -0.19729 | EE8: -0.19175 | EF8: -0.19109
A9: 26664 | B9: NaN | C9: NaN | D9: NaN | E9: NaN | F9: NaN | G9: NaN | H9: NaN | I9: NaN | J9: NaN | K9: NaN | L9: NaN | M9: NaN | N9: NaN | O9: NaN | P9: NaN | Q9: NaN | R9: NaN | S9: NaN | T9: NaN | U9: NaN | V9: NaN | W9: NaN | X9: NaN | Y9: NaN | Z9: NaN | AA9: NaN | AB9: NaN | AC9: NaN | AD9: NaN | AE9: NaN | AF9: NaN | AG9: NaN | AH9: NaN | AI9: NaN | AJ9: NaN | AK9: NaN | AL9: NaN | AM9: NaN | AN9: NaN | AO9: NaN | AP9: NaN | AQ9: NaN | AR9: NaN | AS9: NaN | AT9: NaN | AU9: NaN | AV9: NaN | AW9: NaN | AX9: NaN | AY9: NaN | AZ9: NaN | BA9: NaN | BB9: NaN | BC9: NaN | BD9: NaN | BE9: NaN | BF9: NaN | BG9: NaN | BH9: NaN | BI9: NaN | BJ9: NaN | BK9: NaN | BL9: NaN | BM9: NaN | BN9: NaN | BO9: NaN | BP9: NaN | BQ9: NaN | BR9: NaN | BS9: NaN | BT9: NaN | BU9: NaN | BV9: NaN | BW9: NaN | BX9: NaN | BY9: NaN | BZ9: NaN | CA9: NaN | CB9: NaN | CC9: NaN | CD9: NaN | CE9: NaN | CF9: NaN | CG9: NaN | CH9: NaN | CI9: NaN | CJ9: NaN | CK9: NaN | CL9: NaN | CM9: NaN | CN9: NaN | CO9: NaN | CP9: NaN | CQ9: NaN | CR9: NaN | CS9: NaN | CT9: NaN | CU9: NaN | CV9: NaN | CW9: NaN | CX9: NaN | CY9: NaN | CZ9: NaN | DA9: NaN | DB9: NaN | DC9: NaN | DD9: NaN | DE9: NaN | DF9: NaN | DG9: NaN | DH9: NaN | DI9: NaN | DJ9: NaN | DK9: NaN | DL9: NaN | DM9: NaN | DN9: NaN | DO9: NaN | DP9: -0.34 | DQ9: -0.3 | DR9: -0.29 | DS9: -0.28 | DT9: -0.28 | DU9: -0.27 | DV9: -0.26 | DW9: -0.26 | DX9: -0.25 | DY9: -0.24 | DZ9: -0.24 | EA9: -0.23 | EB9: -0.31157 | EC9: -0.30486 | ED9: -0.29875 | EE9: -0.28778 | EF9: -0.28803
A10: 26754 | B10: 0.56217217 | C10: 0.56443972 | D10: 0.57353568 | E10: 0.5735557 | F10: 0.56835495 | G10: 0.55811433 | H10: 0.54587623 | I10: 0.5439762 | J10: 0.54426921 | K10: 0.54156753 | L10: 0.54191549 | M10: 0.54238702 | N10: 0.54396214 | O10: 0.52795372 | P10: 0.53499706 | Q10: 0.5451251 | R10: 0.55044741 | S10: 0.55500674 | T10: 0.57781713 | U10: 0.58702099 | V10: 0.59436548 | W10: 0.61989754 | X10: 0.60977111 | Y10: 0.63414289 | Z10: 0.59710451 | AA10: 0.69879079 | AB10: 0.65441836 | AC10: 0.65875795 | AD10: 0.57955442 | AE10: 0.56279105 | AF10: 0.66243403 | AG10: 0.6805397 | AH10: 0.55202685 | AI10: 0.69117456 | AJ10: 0.57200585 | AK10: 0.69828424 | AL10: 0.70608074 | AM10: 0.5320107 | AN10: 0.5134492 | AO10: 0.72839572 | AP10: 0.65193852 | AQ10: 0.73720305 | AR10: 0.7401726 | AS10: 0.7464812 | AT10: 0.67808607 | AU10: 0.6991239 | AV10: 0.62084967 | AW10: 0.66385136 | AX10: 0.68409936 | AY10: 0.68104704 | AZ10: 0.65782982 | BA10: 0.67043261 | BB10: 0.68944437 | BC10: 0.73552527 | BD10: 0.72874976 | BE10: 0.65829371 | BF10: 0.70084249 | BG10: 0.70570282 | BH10: 0.62219489 | BI10: 0.73409149 | BJ10: 0.77610507 | BK10: 0.7801256 | BL10: 0.64963201 | BM10: 0.80022953 | BN10: 0.78695846 | BO10: 0.8024542 | BP10: 0.79712053 | BQ10: 0.88389291 | BR10: 0.77710876 | BS10: 0.79356771 | BT10: 0.84411108 | BU10: 0.79473495 | BV10: 0.82453341 | BW10: 0.77522553 | BX10: 0.82344491 | BY10: 0.8710577 | BZ10: 0.82472019 | CA10: 0.83554775 | CB10: 0.79673044 | CC10: 0.86319429 | CD10: 0.82596925 | CE10: 0.89075481 | CF10: 0.91537585 | CG10: 0.83770007 | CH10: 0.82361229 | CI10: 0.82839345 | CJ10: 0.796389 | CK10: 0.82504887 | CL10: 0.80938962 | CM10: 0.83057628 | CN10: 0.86416668 | CO10: 0.81130644 | CP10: 0.84046995 | CQ10: 0.92 | CR10: 0.93 | CS10: 0.94 | CT10: 0.95 | CU10: 0.96 | CV10: 0.9 | CW10: 0.9 | CX10: 0.9 | CY10: 0.91 | CZ10: 0.92 | DA10: 0.92 | DB10: 0.95 | DC10: 0.95 | DD10: 0.95 | DE10: 0.95 | DF10: 0.95 | DG10: 0.96 | DH10: 0.96 | DI10: 0.96 | DJ10: 0.97 | DK10: 1 | DL10: 1.02 | DM10: 1.02 | DN10: 1.02 | DO10: 1.03 | DP10: 1.01 | DQ10: 0.98 | DR10: 0.97 | DS10: 0.97 | DT10: 0.97 | DU10: 0.97 | DV10: 0.99 | DW10: 0.99 | DX10: 0.99 | DY10: 1 | DZ10: 1.02 | EA10: 1.03 | EB10: 1.10265 | EC10: 1.10736 | ED10: 1.11353 | EE10: 1.11339 | EF10: 1.11419
A11: 26845 | B11: 0.61068936 | C11: 0.61456115 | D11: 0.62851944 | E11: 0.62239768 | F11: 0.60993011 | G11: 0.58890257 | H11: 0.58697709 | I11: 0.58356009 | J11: 0.57739691 | K11: 0.57041211 | L11: 0.56815554 | M11: 0.56134383 | N11: 0.55911638 | O11: 0.42193844 | P11: 0.42401151 | Q11: 0.42280741 | R11: 0.41082667 | S11: 0.3978607 | T11: 0.50102521 | U11: 0.50790286 | V11: 0.51549031 | W11: 0.21137215 | X11: 0.51900795 | Y11: 0.23170522 | Z11: 0.43864236 | AA11: 0.3396341 | AB11: 0.26304369 | AC11: 0.26854584 | AD11: 0.44578571 | AE11: 0.42442666 | AF11: 0.39100546 | AG11: 0.28859537 | AH11: 0.39118028 | AI11: 0.30433785 | AJ11: 0.44751641 | AK11: 0.31402237 | AL11: 0.32221326 | AM11: 0.36559846 | AN11: 0.34657871 | AO11: 0.34037971 | AP11: 0.43554537 | AQ11: 0.34735846 | AR11: 0.35525521 | AS11: 0.35677619 | AT11: 0.62460549 | AU11: 0.44010842 | AV11: 0.62719478 | AW11: 0.53474775 | AX11: 0.66445026 | AY11: 0.66705919 | AZ11: 0.66478643 | BA11: 0.67492359 | BB11: 0.53840684 | BC11: 0.62975856 | BD11: 0.59779606 | BE11: 0.58815365 | BF11: 0.540421 | BG11: 0.58607197 | BH11: 0.56408312 | BI11: 0.78200132 | BJ11: 0.67054009 | BK11: 0.79085317 | BL11: 0.72327011 | BM11: 0.82668008 | BN11: 0.81628441 | BO11: 0.85008868 | BP11: 0.85757372 | BQ11: 0.8097086 | BR11: 0.71803642 | BS11: 0.88542776 | BT11: 0.86356973 | BU11: 0.66494309 | BV11: 0.81121936 | BW11: 0.70069445 | BX11: 0.87122171 | BY11: 0.75300055 | BZ11: 0.84982407 | CA11: 0.82472718 | CB11: 0.68372737 | CC11: 0.81201351 | CD11: 0.68381335 | CE11: 0.77133614 | CF11: 0.77966382 | CG11: 0.66141513 | CH11: 0.6625778 | CI11: 0.68764061 | CJ11: 0.70375251 | CK11: 0.56571234 | CL11: 0.70923255 | CM11: 0.70727391 | CN11: 0.64925936 | CO11: 0.63482381 | CP11: 0.60578977 | CQ11: 0.75 | CR11: 0.74 | CS11: 0.74 | CT11: 0.75 | CU11: 0.75 | CV11: 0.72 | CW11: 0.73 | CX11: 0.83 | CY11: 0.84 | CZ11: 0.85 | DA11: 0.85 | DB11: 0.84 | DC11: 0.84 | DD11: 0.85 | DE11: 0.87 | DF11: 0.88 | DG11: 0.89 | DH11: 0.91 | DI11: 0.93 | DJ11: 0.94 | DK11: 0.94 | DL11: 0.93 | DM11: 0.94 | DN11: 0.96 | DO11: 0.97 | DP11: 1.05 | DQ11: 1.08 | DR11: 1.09 | DS11: 1.11 | DT11: 1.12 | DU11: 1.12 | DV11: 1.13 | DW11: 1.12 | DX11: 1.14 | DY11: 1.15 | DZ11: 1.16 | EA11: 1.17 | EB11: 1.08076 | EC11: 1.08737 | ED11: 1.09318 | EE11: 1.10444 | EF11: 1.10381
A12: 26937 | B12: 1.1746037 | C12: 1.1804711 | D12: 1.1856955 | E12: 1.1994761 | F12: 1.2186412 | G12: 1.2368233 | H12: 1.2462577 | I12: 1.2583357 | J12: 1.2760163 | K12: 1.2934593 | L12: 1.3064663 | M12: 1.3233098 | N12: 1.342132 | O12: 1.4277524 | P12: 1.4372094 | Q12: 1.4484526 | R12: 1.4698898 | S12: 1.4926467 | T12: 1.4674573 | U12: 1.4855017 | V12: 1.4903119 | W12: 1.7230134 | X12: 1.5299818 | Y12: 1.7280272 | Z12: 1.6211929 | AA12: 1.7538252 | AB12: 1.7467669 | AC12: 1.7564904 | AD12: 1.6125649 | AE12: 1.6386656 | AF12: 1.769641 | AG12: 1.7956836 | AH12: 1.6679193 | AI12: 1.8101442 | AJ12: 1.8421351 | AK12: 1.8301955 | AL12: 1.8346689 | AM12: 1.7053753 | AN12: 1.6901934 | AO12: 1.8675427 | AP12: 1.8183184 | AQ12: 1.8873724 | AR12: 1.8963916 | AS12: 1.9028803 | AT12: 1.6317257 | AU12: 1.8917439 | AV12: 1.6242643 | AW12: 1.8509584 | AX12: 1.6830524 | AY12: 1.6845971 | AZ12: 1.6750692 | BA12: 1.6797599 | BB12: 1.8523523 | BC12: 1.6846675 | BD12: 1.9005853 | BE12: 1.924122 | BF12: 1.8439453 | BG12: 1.8786058 | BH12: 1.8996166 | BI12: 1.7785363 | BJ12: 1.9727045 | BK12: 1.7910607 | BL12: 2.0221339 | BM12: 1.8295629 | BN12: 1.824673 | BO12: 1.8261381 | BP12: 1.8528575 | BQ12: 1.859038 | BR12: 1.9836639 | BS12: 1.8903481 | BT12: 1.8938305 | BU12: 2.031499 | BV12: 1.9082829 | BW12: 2.022129 | BX12: 1.9095388 | BY12: 1.9711173 | BZ12: 1.9244837 | CA12: 1.9167133 | CB12: 2.0295226 | CC12: 1.9272479 | CD12: 1.9817214 | CE12: 1.914488 | CF12: 1.9123133 | CG12: 1.9501635 | CH12: 1.8687219 | CI12: 1.869864 | CJ12: 1.8515349 | CK12: 2.0261703 | CL12: 1.8925143 | CM12: 1.8906443 | CN12: 2.1192493 | CO12: 2.1044328 | CP12: 2.0748742 | CQ12: 1.96 | CR12: 2 | CS12: 2.01 | CT12: 2.03 | CU12: 2.03 | CV12: 1.94 | CW12: 1.95 | CX12: 1.93 | CY12: 1.94 | CZ12: 1.95 | DA12: 1.95 | DB12: 1.97 | DC12: 1.97 | DD12: 1.97 | DE12: 1.97 | DF12: 1.98 | DG12: 1.99 | DH12: 1.99 | DI12: 2 | DJ12: 2.02 | DK12: 2.02 | DL12: 2.04 | DM12: 2.05 | DN12: 2.06 | DO12: 2.07 | DP12: 2.11 | DQ12: 2.13 | DR12: 2.15 | DS12: 2.16 | DT12: 2.17 | DU12: 2.18 | DV12: 2.18 | DW12: 2.18 | DX12: 2.2 | DY12: 2.2 | DZ12: 2.21 | EA12: 2.22 | EB12: 2.15556 | EC12: 2.15966 | ED12: 2.1642 | EE12: 2.16997 | EF12: 2.17071
A13: 27029 | B13: 0.85462604 | C13: 0.85172678 | D13: 0.85738846 | E13: 0.87138621 | F13: 0.88953036 | G13: 0.90466858 | H13: 0.91252898 | I13: 0.91785247 | J13: 0.92958399 | K13: 0.94042565 | L13: 0.95105628 | M13: 0.9663177 | N13: 0.98375278 | O13: 1.0972618 | P13: 1.1116191 | Q13: 1.1282886 | R13: 1.1555645 | S13: 1.1841113 | T13: 1.1611503 | U13: 1.1663745 | V13: 1.1753547 | W13: 1.5067511 | X13: 1.2100706 | Y13: 1.4927913 | Z13: 1.2647338 | AA13: 1.5708976 | AB13: 1.4970699 | AC13: 1.5018146 | AD13: 1.2907876 | AE13: 1.2939333 | AF13: 1.4903941 | AG13: 1.5336888 | AH13: 1.3120897 | AI13: 1.5336385 | AJ13: 1.4079571 | AK13: 1.5476266 | AL13: 1.5584978 | AM13: 1.3370792 | AN13: 1.3278239 | AO13: 1.587046 | AP13: 1.4651892 | AQ13: 1.6012949 | AR13: 1.6077439 | AS13: 1.6151275 | AT13: 1.2330484 | AU13: 1.5531677 | AV13: 1.2280381 | AW13: 1.4128396 | AX13: 1.2520081 | AY13: 1.2368188 | AZ13: 1.2300928 | BA13: 1.2381939 | BB13: 1.4583326 | BC13: 1.2971761 | BD13: 1.4562963 | BE13: 1.4745373 | BF13: 1.5232105 | BG13: 1.5003237 | BH13: 1.4544247 | BI13: 1.3084531 | BJ13: 1.5764576 | BK13: 1.3380094 | BL13: 1.5514463 | BM13: 1.3488101 | BN13: 1.3522652 | BO13: 1.387042 | BP13: 1.3760116 | BQ13: 1.4701015 | BR13: 1.577269 | BS13: 1.3722141 | BT13: 1.4315802 | BU13: 1.6562233 | BV13: 1.503908 | BW13: 1.5779706 | BX13: 1.4056915 | BY13: 1.5247655 | BZ13: 1.4144212 | CA13: 1.4479139 | CB13: 1.6730611 | CC13: 1.4639283 | CD13: 1.5947045 | CE13: 1.5112772 | CF13: 1.4969278 | CG13: 1.5567761 | CH13: 1.4709703 | CI13: 1.4630611 | CJ13: 1.4630128 | CK13: 1.6744125 | CL13: 1.4601176 | CM13: 1.4714387 | CN13: 1.7328355 | CO13: 1.6802234 | CP13: 1.7657761 | CQ13: 1.56 | CR13: 1.61 | CS13: 1.61 | CT13: 1.62 | CU13: 1.63 | CV13: 1.58 | CW13: 1.58 | CX13: 1.51 | CY13: 1.51 | CZ13: 1.52 | DA13: 1.52 | DB13: 1.56 | DC13: 1.56 | DD13: 1.55 | DE13: 1.54 | DF13: 1.54 | DG13: 1.55 | DH13: 1.55 | DI13: 1.54 | DJ13: 1.54 | DK13: 1.57 | DL13: 1.6 | DM13: 1.61 | DN13: 1.61 | DO13: 1.62 | DP13: 1.57 | DQ13: 1.54 | DR13: 1.54 | DS13: 1.54 | DT13: 1.54 | DU13: 1.54 | DV13: 1.54 | DW13: 1.54 | DX13: 1.54 | DY13: 1.54 | DZ13: 1.55 | EA13: 1.56 | EB13: 1.59451 | EC13: 1.59688 | ED13: 1.59773 | EE13: 1.59124 | EF13: 1.59313
A14: 27119 | B14: 0.53095456 | C14: 0.54047295 | D14: 0.55733983 | E14: 0.54979524 | F14: 0.53571707 | G14: 0.50892911 | H14: 0.51656788 | I14: 0.5091191 | J14: 0.50227378 | K14: 0.49229946 | L14: 0.48874993 | M14: 0.47979747 | N14: 0.48001991 | O14: 0.30731586 | P14: 0.30993035 | Q14: 0.30500062 | R14: 0.29080246 | S14: 0.27388716 | T14: 0.396317 | U14: 0.38274584 | V14: 0.39059656 | W14: -0.034848279 | X14: 0.39113799 | Y14: -0.014566385 | Z14: 0.32452676 | AA14: 0.19800438 | AB14: 0.014989347 | AC14: 0.0230952 | AD14: 0.31537539 | AE14: 0.27690932 | AF14: 0.22669755 | AG14: 0.02382996 | AH14: 0.24185116 | AI14: 0.040033187 | AJ14: 0.21201754 | AK14: 0.042703329 | AL14: 0.048952554 | AM14: 0.21279001 | AN14: 0.21377886 | AO14: 0.051271229 | AP14: 0.27622977 | AQ14: 0.056276025 | AR14: 0.065015099 | AS14: 0.064710621 | AT14: 0.33285993 | AU14: 0.22568225 | AV14: 0.38665948 | AW14: 0.25080807 | AX14: 0.37308661 | AY14: 0.36989081 | AZ14: 0.38092259 | BA14: 0.39297109 | BB14: 0.30440113 | BC14: 0.32707812 | BD14: 0.29008872 | BE14: 0.34655 | BF14: 0.34212134 | BG14: 0.38378754 | BH14: 0.40269436 | BI14: 0.49986089 | BJ14: 0.41171798 | BK14: 0.50873462 | BL14: 0.53679899 | BM14: 0.526968 | BN14: 0.52904722 | BO14: 0.60818325 | BP14: 0.57206209 | BQ14: 0.51743172 | BR14: 0.48533576 | BS14: 0.60720592 | BT14: 0.57882864 | BU14: 0.44713299 | BV14: 0.59345916 | BW14: 0.42870551 | BX14: 0.58006797 | BY14: 0.42483165 | BZ14: 0.54720094 | CA14: 0.5376427 | CB14: 0.51867326 | CC14: 0.50409958 | CD14: 0.44547795 | CE14: 0.49287784 | CF14: 0.47901057 | CG14: 0.41123579 | CH14: 0.38424731 | CI14: 0.41550279 | CJ14: 0.49408246 | CK14: 0.34500198 | CL14: 0.44569681 | CM14: 0.44298334 | CN14: 0.40148984 | CO14: 0.40238512 | CP14: 0.45690971 | CQ14: 0.5 | CR14: 0.49 | CS14: 0.48 | CT14: 0.48 | CU14: 0.48 | CV14: 0.53 | CW14: 0.53 | CX14: 0.6 | CY14: 0.61 | CZ14: 0.62 | DA14: 0.62 | DB14: 0.6 | DC14: 0.61 | DD14: 0.62 | DE14: 0.64 | DF14: 0.65 | DG14: 0.66 | DH14: 0.68 | DI14: 0.7 | DJ14: 0.72 | DK14: 0.7 | DL14: 0.69 | DM14: 0.7 | DN14: 0.71 | DO14: 0.72 | DP14: 0.81 | DQ14: 0.86 | DR14: 0.88 | DS14: 0.9 | DT14: 0.91 | DU14: 0.92 | DV14: 0.93 | DW14: 0.92 | DX14: 0.94 | DY14: 0.95 | DZ14: 0.95 | EA14: 0.95 | EB14: 0.68358 | EC14: 0.68693 | ED14: 0.69 | EE14: 0.6997 | EF14: 0.69995
A15: 27210 | B15: 1.9319993 | C15: 1.9195464 | D15: 1.92084 | E15: 1.956431 | F15: 2.0020196 | G15: 2.0526905 | H15: 2.0524045 | I15: 2.078292 | J15: 2.1159844 | K15: 2.1515762 | L15: 2.1787111 | M15: 2.2187891 | N15: 2.2509321 | O15: 2.6108436 | P15: 2.6335366 | Q15: 2.660146 | R15: 2.7187916 | S15: 2.7781462 | T15: 2.6146058 | U15: 2.6495375 | V15: 2.6521268 | W15: 3.7149157 | X15: 2.7509325 | Y15: 3.69092 | Z15: 3.0909097 | AA15: 3.6357406 | AB15: 3.6907186 | AC15: 3.7018739 | AD15: 2.9538516 | AE15: 3.012446 | AF15: 3.5309509 | AG15: 3.7498383 | AH15: 3.0970752 | AI15: 3.770294 | AJ15: 3.4419282 | AK15: 3.787246 | AL15: 3.804006 | AM15: 3.1776789 | AN15: 3.1552053 | AO15: 3.8528266 | AP15: 3.5262159 | AQ15: 3.8862318 | AR15: 3.9075098 | AS15: 3.9228664 | AT15: 3.5122745 | AU15: 3.8199827 | AV15: 3.4459678 | AW15: 3.7961313 | AX15: 3.5538767 | AY15: 3.5633151 | AZ15: 3.5238741 | BA15: 3.5279753 | BB15: 3.7898015 | BC15: 3.6143443 | BD15: 3.8222651 | BE15: 3.7420691 | BF15: 3.733877 | BG15: 3.8081166 | BH15: 3.5821879 | BI15: 3.6455656 | BJ15: 3.9582885 | BK15: 3.6903998 | BL15: 3.9031186 | BM15: 3.7438895 | BN15: 3.7272303 | BO15: 3.6738063 | BP15: 3.7158818 | BQ15: 3.8379442 | BR15: 3.9181721 | BS15: 3.7282196 | BT15: 3.816287 | BU15: 3.9958698 | BV15: 3.8363441 | BW15: 4.0731002 | BX15: 3.8718664 | BY15: 4.081193 | BZ15: 3.9321596 | CA15: 3.9611607 | CB15: 4.1366809 | CC15: 4.0328495 | CD15: 4.0991341 | CE15: 4.0964203 | CF15: 4.1218433 | CG15: 4.1626237 | CH15: 4.0815845 | CI15: 4.0720146 | CJ15: 3.9961986 | CK15: 4.2617618 | CL15: 4.0783895 | CM15: 4.0870022 | CN15: 4.4245266 | CO15: 4.3257088 | CP15: 4.3382485 | CQ15: 4.23 | CR15: 4.26 | CS15: 4.28 | CT15: 4.3 | CU15: 4.32 | CV15: 4.26 | CW15: 4.26 | CX15: 4.22 | CY15: 4.23 | CZ15: 4.24 | DA15: 4.24 | DB15: 4.28 | DC15: 4.28 | DD15: 4.28 | DE15: 4.27 | DF15: 4.27 | DG15: 4.29 | DH15: 4.29 | DI15: 4.29 | DJ15: 4.3 | DK15: 4.33 | DL15: 4.37 | DM15: 4.38 | DN15: 4.4 | DO15: 4.4 | DP15: 4.39 | DQ15: 4.35 | DR15: 4.35 | DS15: 4.35 | DT15: 4.35 | DU15: 4.36 | DV15: 4.37 | DW15: 4.38 | DX15: 4.38 | DY15: 4.39 | DZ15: 4.42 | EA15: 4.44 | EB15: 4.53631 | EC15: 4.54611 | ED15: 4.55333 | EE15: 4.54886 | EF15: 4.55252
A16: 27302 | B16: 1.6380513 | C16: 1.6206033 | D16: 1.6152138 | E16: 1.649303 | F16: 1.6971507 | G16: 1.7523353 | H16: 1.7618953 | I16: 1.7906142 | J16: 1.8311963 | K16: 1.867446 | L16: 1.8982572 | M16: 1.9376071 | N16: 1.9765669 | O16: 2.3087802 | P16: 2.3250678 | Q16: 2.3491216 | R16: 2.4078609 | S16: 2.469259 | T16: 2.3356274 | U16: 2.3718389 | V16: 2.3733425 | W16: 3.2406322 | X16: 2.467261 | Y16: 3.2215869 | Z16: 2.7802847 | AA16: 3.1256118 | AB16: 3.2183512 | AC16: 3.2273959 | AD16: 2.7231426 | AE16: 2.7846279 | AF16: 3.1233784 | AG16: 3.2822687 | AH16: 2.8814761 | AI16: 3.3005671 | AJ16: 3.329179 | AK16: 3.3206767 | AL16: 3.3310544 | AM16: 2.9755128 | AN16: 2.984707 | AO16: 3.3757376 | AP16: 3.2356872 | AQ16: 3.4090392 | AR16: 3.4268778 | AS16: 3.4385362 | AT16: 2.8641754 | AU16: 3.3676057 | AV16: 2.8478679 | AW16: 3.2748726 | AX16: 2.8919877 | AY16: 2.9228805 | AZ16: 2.8900466 | BA16: 2.8675444 | BB16: 3.2824895 | BC16: 2.8966397 | BD16: 3.2661123 | BE16: 3.3502228 | BF16: 3.2027261 | BG16: 3.2965844 | BH16: 3.3233672 | BI16: 3.0028424 | BJ16: 3.4352643 | BK16: 3.0371464 | BL16: 3.6508775 | BM16: 3.0931594 | BN16: 3.0879028 | BO16: 3.0706634 | BP16: 3.0973871 | BQ16: 3.0565786 | BR16: 3.4491594 | BS16: 3.1381465 | BT16: 3.1578652 | BU16: 3.5485866 | BV16: 3.1563203 | BW16: 3.5698361 | BX16: 3.2335277 | BY16: 3.4096153 | BZ16: 3.2837253 | CA16: 3.2706528 | CB16: 3.6821389 | CC16: 3.3542733 | CD16: 3.4989302 | CE16: 3.3963088 | CF16: 3.3930252 | CG16: 3.5385747 | CH16: 3.3947797 | CI16: 3.3912894 | CJ16: 3.3962478 | CK16: 3.7401584 | CL16: 3.414432 | CM16: 3.4138314 | CN16: 3.8512296 | CO16: 3.87913 | CP16: 3.8465772 | CQ16: 3.49 | CR16: 3.54 | CS16: 3.55 | CT16: 3.57 | CU16: 3.58 | CV16: 3.57 | CW16: 3.57 | CX16: 3.48 | CY16: 3.49 | CZ16: 3.5 | DA16: 3.5 | DB16: 3.53 | DC16: 3.53 | DD16: 3.53 | DE16: 3.54 | DF16: 3.54 | DG16: 3.55 | DH16: 3.56 | DI16: 3.56 | DJ16: 3.57 | DK16: 3.59 | DL16: 3.61 | DM16: 3.63 | DN16: 3.64 | DO16: 3.65 | DP16: 3.64 | DQ16: 3.67 | DR16: 3.7 | DS16: 3.71 | DT16: 3.73 | DU16: 3.74 | DV16: 3.75 | DW16: 3.76 | DX16: 3.77 | DY16: 3.79 | DZ16: 3.8 | EA16: 3.81 | EB16: 3.78257 | EC16: 3.79143 | ED16: 3.79965 | EE16: 3.80684 | EF16: 3.80957
A17: 27394 | B17: 0.80172892 | C17: 0.78883803 | D17: 0.79199587 | E17: 0.81009829 | F17: 0.83545192 | G17: 0.85751861 | H17: 0.88432 | I17: 0.89465861 | J17: 0.91604683 | K17: 0.93194192 | L17: 0.94841802 | M17: 0.968659 | N17: 0.98887806 | O17: 1.1133221 | P17: 1.1243454 | Q17: 1.135912 | R17: 1.1657746 | S17: 1.2025473 | T17: 1.2092592 | U17: 1.2206478 | V17: 1.2273338 | W17: 1.7107451 | X17: 1.2713357 | Y17: 1.714489 | Z17: 1.4138879 | AA17: 1.6425063 | AB17: 1.7340767 | AC17: 1.7499379 | AD17: 1.4732519 | AE17: 1.5091191 | AF17: 1.6736072 | AG17: 1.7917397 | AH17: 1.5788533 | AI17: 1.8137172 | AJ17: 1.7025599 | AK17: 1.8332666 | AL17: 1.8439695 | AM17: 1.6528267 | AN17: 1.6523864 | AO17: 1.8761944 | AP17: 1.7679741 | AQ17: 1.8980974 | AR17: 1.910355 | AS17: 1.9177096 | AT17: 1.6304861 | AU17: 1.8671629 | AV17: 1.6601607 | AW17: 1.8526055 | AX17: 1.6545283 | AY17: 1.6603625 | AZ17: 1.656252 | BA17: 1.6605954 | BB17: 1.8857142 | BC17: 1.6865862 | BD17: 1.8733799 | BE17: 1.8759658 | BF17: 1.8877083 | BG17: 1.9184733 | BH17: 1.8518597 | BI17: 1.7277963 | BJ17: 1.9779771 | BK17: 1.7495494 | BL17: 2.0399871 | BM17: 1.7684761 | BN17: 1.7778047 | BO17: 1.7875399 | BP17: 1.7961202 | BQ17: 1.899179 | BR17: 2.0110043 | BS17: 1.8062495 | BT17: 1.8761454 | BU17: 2.1070722 | BV17: 1.9619375 | BW17: 2.0429984 | BX17: 1.8886214 | BY17: 2.0073604 | BZ17: 1.9407791 | CA17: 1.9683235 | CB17: 2.1904696 | CC17: 1.9719439 | CD17: 2.0779335 | CE17: 2.0191858 | CF17: 2.0326278 | CG17: 2.0873553 | CH17: 2.0620999 | CI17: 2.0581034 | CJ17: 2.0666184 | CK17: 2.257992 | CL17: 2.0897878 | CM17: 2.0993388 | CN17: 2.3083602 | CO17: 2.2915997 | CP17: 2.3342822 | CQ17: 1.91 | CR17: 1.95 | CS17: 1.96 | CT17: 1.97 | CU17: 1.98 | CV17: 2 | CW17: 2 | CX17: 1.9 | CY17: 1.91 | CZ17: 1.91 | DA17: 1.92 | DB17: 1.96 | DC17: 1.96 | DD17: 1.96 | DE17: 1.95 | DF17: 1.95 | DG17: 1.99 | DH17: 2 | DI17: 2 | DJ17: 2 | DK17: 2.01 | DL17: 2.03 | DM17: 2.04 | DN17: 2.04 | DO17: 2.05 | DP17: 1.94 | DQ17: 1.92 | DR17: 1.92 | DS17: 1.92 | DT17: 1.93 | DU17: 1.93 | DV17: 1.94 | DW17: 1.94 | DX17: 1.93 | DY17: 1.94 | DZ17: 1.95 | EA17: 1.95 | EB17: 2.1755 | EC17: 2.17811 | ED17: 2.18198 | EE17: 2.18027 | EF17: 2.18344
A18: 27484 | B18: -0.46686948 | C18: -0.46071657 | D18: -0.46039751 | E18: -0.46085516 | F18: -0.46504205 | G18: -0.46928297 | H18: -0.46782213 | I18: -0.47043716 | J18: -0.47242826 | K18: -0.479524 | L18: -0.47975885 | M18: -0.47824345 | N18: -0.47665802 | O18: -0.45478023 | P18: -0.45360102 | Q18: -0.44970368 | R18: -0.44148392 | S18: -0.42583288 | T18: -0.43100999 | U18: -0.44154684 | V18: -0.43125426 | W18: -0.13833962 | X18: -0.44135881 | Y18: -0.12519112 | Z18: -0.36069868 | AA18: -0.15956561 | AB18: -0.10144094 | AC18: -0.093449426 | AD18: -0.36192415 | AE18: -0.34182821 | AF18: -0.208668 | AG18: -0.07982288 | AH18: -0.33470865 | AI18: -0.065017032 | AJ18: -0.21860534 | AK18: -0.057536555 | AL18: -0.051447085 | AM18: -0.34247853 | AN18: -0.34604631 | AO18: -0.045837505 | AP18: -0.26739835 | AQ18: -0.041438927 | AR18: -0.034441324 | AS18: -0.035919169 | AT18: -0.22673378 | AU18: -0.19221006 | AV18: -0.20734325 | AW18: -0.26340665 | AX18: -0.22527932 | AY18: -0.22422829 | AZ18: -0.21253805 | BA18: -0.21676961 | BB18: -0.26294028 | BC18: -0.21963711 | BD18: -0.23268244 | BE18: -0.23118629 | BF18: -0.22767631 | BG18: -0.21946258 | BH18: -0.25232272 | BI18: -0.1546349 | BJ18: -0.19198894 | BK18: -0.14943647 | BL18: -0.13499055 | BM18: -0.11823939 | BN18: -0.10494226 | BO18: -0.086586227 | BP18: -0.072968213 | BQ18: -0.078459594 | BR18: -0.16177404 | BS18: -0.042241071 | BT18: -0.046242132 | BU18: -0.15121521 | BV18: -0.03763483 | BW18: -0.10541736 | BX18: -0.015389287 | BY18: -0.076611769 | BZ18: -0.00926774 | CA18: 0.012162903 | CB18: -0.071392796 | CC18: -0.014414447 | CD18: -0.075864699 | CE18: 0.025035063 | CF18: 0.039556887 | CG18: 0.032812848 | CH18: 0.071155795 | CI18: 0.092084756 | CJ18: 0.11249005 | CK18: 0.059790089 | CL18: 0.13485902 | CM18: 0.12755248 | CN18: 0.078429885 | CO18: 0.079286627 | CP18: 0.10660099 | CQ18: 0.06 | CR18: 0.07 | CS18: 0.07 | CT18: 0.08 | CU18: 0.08 | CV18: 0.08 | CW18: 0.08 | CX18: 0.09 | CY18: 0.1 | CZ18: 0.1 | DA18: 0.11 | DB18: 0.13 | DC18: 0.13 | DD18: 0.13 | DE18: 0.13 | DF18: 0.14 | DG18: 0.15 | DH18: 0.17 | DI18: 0.17 | DJ18: 0.18 | DK18: 0.18 | DL18: 0.18 | DM18: 0.18 | DN18: 0.19 | DO18: 0.19 | DP18: 0.19 | DQ18: 0.19 | DR18: 0.19 | DS18: 0.19 | DT18: 0.19 | DU18: 0.2 | DV18: 0.21 | DW18: 0.21 | DX18: 0.22 | DY18: 0.22 | DZ18: 0.23 | EA18: 0.24 | EB18: 0.38712 | EC18: 0.3929 | ED18: 0.39528 | EE18: 0.39863 | EF18: 0.39968
A19: 27575 | B19: -0.64468967 | C19: -0.63098152 | D19: -0.6267 | E19: -0.63655709 | F19: -0.656428 | G19: -0.67997327 | H19: -0.68419602 | I19: -0.69196709 | J19: -0.70381559 | K19: -0.71771906 | L19: -0.72454725 | M19: -0.73240161 | N19: -0.73785108 | O19: -0.79916283 | P19: -0.79718993 | Q19: -0.79421179 | R19: -0.79779129 | S19: -0.79473901 | T19: -0.76896742 | U19: -0.77506469 | V19: -0.76526422 | W19: -0.62791704 | X19: -0.78929268 | Y19: -0.6050512 | Z19: -0.79009154 | AA19: -0.71809941 | AB19: -0.57679607 | AC19: -0.57270985 | AD19: -0.79126026 | AE19: -0.80230674 | AF19: -0.77636555 | AG19: -0.566775 | AH19: -0.8106748 | AI19: -0.55579975 | AJ19: -0.7527668 | AK19: -0.54962597 | AL19: -0.54551415 | AM19: -0.82989642 | AN19: -0.82016127 | AO19: -0.54694224 | AP19: -0.8122201 | AQ19: -0.54626953 | AR19: -0.5451547 | AS19: -0.54708809 | AT19: -0.81415995 | AU19: -0.78427769 | AV19: -0.81204081 | AW19: -0.84859127 | AX19: -0.81292928 | AY19: -0.82293169 | AZ19: -0.80317896 | BA19: -0.80004042 | BB19: -0.84243833 | BC19: -0.77270228 | BD19: -0.85859332 | BE19: -0.85311353 | BF19: -0.84158997 | BG19: -0.83273099 | BH19: -0.83260355 | BI19: -0.76689286 | BJ19: -0.83150597 | BK19: -0.74952354 | BL19: -0.87717519 | BM19: -0.73710945 | BN19: -0.72425363 | BO19: -0.70065115 | BP19: -0.70230001 | BQ19: -0.67326376 | BR19: -0.81174159 | BS19: -0.67799135 | BT19: -0.67459833 | BU19: -0.80893832 | BV19: -0.67675275 | BW19: -0.78856118 | BX19: -0.67111762 | BY19: -0.74327417 | BZ19: -0.67908734 | CA19: -0.66290496 | CB19: -0.79962552 | CC19: -0.68488447 | CD19: -0.74300962 | CE19: -0.66383719 | CF19: -0.6474407 | CG19: -0.65053111 | CH19: -0.6221009 | CI19: -0.61218298 | CJ19: -0.60062939 | CK19: -0.67724793 | CL19: -0.59717581 | CM19: -0.58732543 | CN19: -0.68383151 | CO19: -0.6852688 | CP19: -0.65826388 | CQ19: -0.6 | CR19: -0.58 | CS19: -0.58 | CT19: -0.58 | CU19: -0.57 | CV19: -0.61 | CW19: -0.61 | CX19: -0.62 | CY19: -0.61 | CZ19: -0.61 | DA19: -0.6 | DB19: -0.58 | DC19: -0.58 | DD19: -0.58 | DE19: -0.58 | DF19: -0.58 | DG19: -0.59 | DH19: -0.59 | DI19: -0.59 | DJ19: -0.59 | DK19: -0.57 | DL19: -0.56 | DM19: -0.56 | DN19: -0.56 | DO19: -0.56 | DP19: -0.62 | DQ19: -0.64 | DR19: -0.64 | DS19: -0.65 | DT19: -0.65 | DU19: -0.65 | DV19: -0.64 | DW19: -0.64 | DX19: -0.64 | DY19: -0.64 | DZ19: -0.63 | EA19: -0.62 | EB19: -0.45595 | EC19: -0.45219 | ED19: -0.44965 | EE19: -0.44798 | EF19: -0.44736
A20: 27667 | B20: -0.24430042 | C20: -0.23367915 | D20: -0.22738242 | E20: -0.23781349 | F20: -0.25828157 | G20: -0.28352045 | H20: -0.30003493 | I20: -0.30592515 | J20: -0.31538539 | K20: -0.32603995 | L20: -0.33191619 | M20: -0.34012144 | N20: -0.34533517 | O20: -0.40798694 | P20: -0.40442289 | Q20: -0.39835339 | R20: -0.40159009 | S20: -0.40150856 | T20: -0.37660016 | U20: -0.37184145 | V20: -0.36498916 | W20: -0.28071231 | X20: -0.37544855 | Y20: -0.25992302 | Z20: -0.41416773 | AA20: -0.40914644 | AB20: -0.23584267 | AC20: -0.23226512 | AD20: -0.41789632 | AE20: -0.44357836 | AF20: -0.45078127 | AG20: -0.22418616 | AH20: -0.45024393 | AI20: -0.21196558 | AJ20: -0.38818842 | AK20: -0.20739088 | AL20: -0.2035123 | AM20: -0.4734546 | AN20: -0.4675995 | AO20: -0.20089649 | AP20: -0.44821715 | AQ20: -0.19759912 | AR20: -0.19631349 | AS20: -0.19718907 | AT20: -0.52261117 | AU20: -0.44207748 | AV20: -0.56864646 | AW20: -0.51259261 | AX20: -0.52598748 | AY20: -0.52555277 | AZ20: -0.51854283 | BA20: -0.53037204 | BB20: -0.49950086 | BC20: -0.49410887 | BD20: -0.50418347 | BE20: -0.50793573 | BF20: -0.55031029 | BG20: -0.51587591 | BH20: -0.50625846 | BI20: -0.4864812 | BJ20: -0.49535495 | BK20: -0.46531569 | BL20: -0.55543546 | BM20: -0.4392378 | BN20: -0.43443312 | BO20: -0.424804 | BP20: -0.41007636 | BQ20: -0.42337024 | BR20: -0.46011776 | BS20: -0.37434199 | BT20: -0.38940261 | BU20: -0.45844911 | BV20: -0.43044193 | BW20: -0.44498446 | BX20: -0.37522409 | BY20: -0.42221815 | BZ20: -0.38306162 | CA20: -0.38299532 | CB20: -0.48382489 | CC20: -0.3795541 | CD20: -0.43512243 | CE20: -0.37639755 | CF20: -0.3630702 | CG20: -0.35497237 | CH20: -0.34960478 | CI20: -0.36144696 | CJ20: -0.38460129 | CK20: -0.41218408 | CL20: -0.35632393 | CM20: -0.34851772 | CN20: -0.38919739 | CO20: -0.39418205 | CP20: -0.39856223 | CQ20: -0.34 | CR20: -0.31 | CS20: -0.31 | CT20: -0.3 | CU20: -0.3 | CV20: -0.36 | CW20: -0.35 | CX20: -0.37 | CY20: -0.36 | CZ20: -0.36 | DA20: -0.35 | DB20: -0.32 | DC20: -0.33 | DD20: -0.32 | DE20: -0.33 | DF20: -0.33 | DG20: -0.33 | DH20: -0.33 | DI20: -0.33 | DJ20: -0.33 | DK20: -0.32 | DL20: -0.3 | DM20: -0.29 | DN20: -0.3 | DO20: -0.3 | DP20: -0.34 | DQ20: -0.35 | DR20: -0.36 | DS20: -0.36 | DT20: -0.36 | DU20: -0.36 | DV20: -0.35 | DW20: -0.35 | DX20: -0.35 | DY20: -0.34 | DZ20: -0.34 | EA20: -0.32 | EB20: -0.18873 | EC20: -0.18539 | ED20: -0.18189 | EE20: -0.17968 | EF20: -0.17883
A21: 27759 | B21: -0.65776862 | C21: -0.64574395 | D21: -0.64529506 | E21: -0.65150627 | F21: -0.66389909 | G21: -0.67645205 | H21: -0.68122669 | I21: -0.68530608 | J21: -0.68978916 | K21: -0.69546581 | L21: -0.69726963 | M21: -0.69922533 | N21: -0.69658949 | O21: -0.69374059 | P21: -0.68863486 | Q21: -0.6773354 | R21: -0.6684167 | S21: -0.65066387 | T21: -0.64819234 | U21: -0.64276965 | V21: -0.63485962 | W21: -0.55668978 | X21: -0.6487054 | Y21: -0.53893972 | Z21: -0.62812781 | AA21: -0.54940214 | AB21: -0.51480154 | AC21: -0.51068589 | AD21: -0.61464978 | AE21: -0.62190037 | AF21: -0.59536534 | AG21: -0.49435245 | AH21: -0.60508521 | AI21: -0.48430173 | AJ21: -0.55006627 | AK21: -0.47701631 | AL21: -0.47049167 | AM21: -0.60115284 | AN21: -0.5925855 | AO21: -0.46546089 | AP21: -0.60395853 | AQ21: -0.46057084 | AR21: -0.4587631 | AS21: -0.46081024 | AT21: -0.77914524 | AU21: -0.62853748 | AV21: -0.80934405 | AW21: -0.74928689 | AX21: -0.79569903 | AY21: -0.7886957 | AZ21: -0.78680769 | BA21: -0.79521863 | BB21: -0.74151407 | BC21: -0.75757725 | BD21: -0.72772703 | BE21: -0.71645664 | BF21: -0.74866891 | BG21: -0.73364078 | BH21: -0.69689354 | BI21: -0.7646701 | BJ21: -0.72430945 | BK21: -0.75128122 | BL21: -0.75228415 | BM21: -0.71859859 | BN21: -0.70949672 | BO21: -0.69943675 | BP21: -0.68748116 | BQ21: -0.68381116 | BR21: -0.69181383 | BS21: -0.66399997 | BT21: -0.66123248 | BU21: -0.65748318 | BV21: -0.67883872 | BW21: -0.64638968 | BX21: -0.63930483 | BY21: -0.65141045 | BZ21: -0.6336809 | CA21: -0.62941815 | CB21: -0.69303883 | CC21: -0.62665909 | CD21: -0.63375166 | CE21: -0.59230367 | CF21: -0.5751283 | CG21: -0.54741662 | CH21: -0.52406442 | CI21: -0.53317404 | CJ21: -0.5421031 | CK21: -0.53306425 | CL21: -0.5181824 | CM21: -0.50577669 | CN21: -0.53054222 | CO21: -0.5082188 | CP21: -0.51504692 | CQ21: -0.5 | CR21: -0.48 | CS21: -0.48 | CT21: -0.47 | CU21: -0.47 | CV21: -0.5 | CW21: -0.5 | CX21: -0.54 | CY21: -0.54 | CZ21: -0.53 | DA21: -0.53 | DB21: -0.5 | DC21: -0.5 | DD21: -0.5 | DE21: -0.5 | DF21: -0.5 | DG21: -0.5 | DH21: -0.51 | DI21: -0.51 | DJ21: -0.51 | DK21: -0.5 | DL21: -0.48 | DM21: -0.48 | DN21: -0.49 | DO21: -0.48 | DP21: -0.54 | DQ21: -0.56 | DR21: -0.57 | DS21: -0.57 | DT21: -0.57 | DU21: -0.57 | DV21: -0.56 | DW21: -0.56 | DX21: -0.56 | DY21: -0.56 | DZ21: -0.55 | EA21: -0.54 | EB21: -0.40362 | EC21: -0.39747 | ED21: -0.39385 | EE21: -0.39294 | EF21: -0.39102
... A70: 32233 | B70: -0.79487857 | C70: -0.67376991 | D70: -0.67804151 | E70: -0.67509552 | F70: -0.64366178 | G70: -0.64114279 | H70: -0.57394735 | I70: -0.58811354 | J70: -0.5932877 | K70: -0.59965684 | L70: -0.61516336 | M70: -0.62176736 | N70: -0.62753935 | O70: -0.45696429 | P70: -0.44025699 | Q70: -0.40893088 | R70: -0.38120275 | S70: -0.35606561 | T70: -0.52611466 | U70: -0.49603706 | V70: -0.46804344 | W70: -0.34225383 | X70: -0.43892107 | Y70: -0.30868487 | Z70: -0.30773488 | AA70: -0.21677964 | AB70: -0.27232366 | AC70: -0.26138572 | AD70: -0.30412487 | AE70: -0.27754054 | AF70: -0.14699425 | AG70: -0.22165851 | AH70: -0.25890389 | AI70: -0.19481603 | AJ70: -0.12149498 | AK70: -0.17421604 | AL70: -0.16886417 | AM70: -0.21014352 | AN70: -0.2011465 | AO70: -0.15076359 | AP70: -0.13855226 | AQ70: -0.13524847 | AR70: -0.131513 | AS70: -0.12990123 | AT70: 0.12582218 | AU70: -0.0012546686 | AV70: 0.10106934 | AW70: 0.047940109 | AX70: 0.095708226 | AY70: 0.076666023 | AZ70: 0.056601766 | BA70: 0.034720091 | BB70: -0.016769397 | BC70: 0.025457337 | BD70: -0.046409235 | BE70: -0.099016672 | BF70: -0.025674977 | BG70: -0.027287109 | BH70: -0.1175299 | BI70: 0.026515499 | BJ70: -0.018335106 | BK70: 0.037413451 | BL70: 0.01512807 | BM70: 0.044268251 | BN70: 0.048916691 | BO70: 0.048124062 | BP70: 0.046349509 | BQ70: 0.065821781 | BR70: 0.038875698 | BS70: 0.053781759 | BT70: 0.055914968 | BU70: 0.034576533 | BV70: 0.058884808 | BW70: 0.03042049 | BX70: 0.068209178 | BY70: 0.045194868 | BZ70: 0.074319679 | CA70: 0.072871765 | CB70: 0.063523333 | CC70: 0.10244429 | CD70: 0.097064686 | CE70: 0.11187954 | CF70: 0.098846903 | CG70: 0.054210431 | CH70: -0.0097843158 | CI70: -0.048071635 | CJ70: -0.058056884 | CK70: -0.068365675 | CL70: -0.070577484 | CM70: -0.050807084 | CN70: -0.038717759 | CO70: -0.030538286 | CP70: -0.013794679 | CQ70: 0.07 | CR70: 0.09 | CS70: 0.08 | CT70: 0.08 | CU70: 0.09 | CV70: 0.11 | CW70: 0.12 | CX70: -0.03 | CY70: -0.02 | CZ70: -0.01 | DA70: -0.01 | DB70: 0.03 | DC70: 0.03 | DD70: 0.03 | DE70: 0.03 | DF70: 0.03 | DG70: 0.04 | DH70: 0.03 | DI70: 0.03 | DJ70: 0.02 | DK70: 0.04 | DL70: 0.07 | DM70: 0.07 | DN70: 0.07 | DO70: 0.07 | DP70: -0.01 | DQ70: -0.1 | DR70: -0.11 | DS70: -0.11 | DT70: -0.12 | DU70: -0.12 | DV70: -0.11 | DW70: -0.1 | DX70: -0.12 | DY70: -0.12 | DZ70: -0.12 | EA70: -0.11 | EB70: 0.01083 | EC70: 0.0132 | ED70: 0.01543 | EE70: 0.00436 | EF70: 0.00597
A71: 32324 | B71: NaN | C71: -0.55926037 | D71: -0.44454895 | E71: -0.44430999 | F71: -0.4448098 | G71: -0.44620384 | H71: -0.40717446 | I71: -0.41655866 | J71: -0.4174435 | K71: -0.45129859 | L71: -0.46313327 | M71: -0.47195175 | N71: -0.4768773 | O71: -0.19749925 | P71: -0.17601518 | Q71: -0.14197542 | R71: -0.11783184 | S71: -0.10018645 | T71: -0.23542039 | U71: -0.22802007 | V71: -0.20450854 | W71: -0.15362342 | X71: -0.17458473 | Y71: -0.11987979 | Z71: -0.078384207 | AA71: -0.03976272 | AB71: -0.08451094 | AC71: -0.076084924 | AD71: -0.084771498 | AE71: -0.06650717 | AF71: 0.018006033 | AG71: -0.032427803 | AH71: -0.051705294 | AI71: -0.012662293 | AJ71: 0.044071984 | AK71: 0.0080022806 | AL71: 0.01793423 | AM71: -0.011152681 | AN71: -0.0039722022 | AO71: 0.039137175 | AP71: 0.049980537 | AQ71: 0.054598212 | AR71: 0.0589546 | AS71: 0.061573677 | AT71: 0.18403594 | AU71: 0.14701858 | AV71: 0.13383015 | AW71: 0.15727251 | AX71: 0.13663287 | AY71: 0.15986435 | AZ71: 0.14146075 | BA71: 0.11364914 | BB71: 0.090422257 | BC71: 0.11258535 | BD71: 0.060620321 | BE71: 0.024497672 | BF71: 0.079380533 | BG71: 0.075240836 | BH71: 0.027201831 | BI71: 0.12293409 | BJ71: 0.078503426 | BK71: 0.13926705 | BL71: 0.11193229 | BM71: 0.1412355 | BN71: 0.14442669 | BO71: 0.11595806 | BP71: 0.098872422 | BQ71: 0.11975814 | BR71: 0.12448752 | BS71: 0.095303867 | BT71: 0.12127646 | BU71: 0.12275596 | BV71: 0.12896269 | BW71: 0.11376826 | BX71: 0.12276309 | BY71: 0.12424013 | BZ71: 0.13404373 | CA71: 0.1329375 | CB71: 0.15691328 | CC71: 0.21936176 | CD71: 0.23061466 | CE71: 0.24075165 | CF71: 0.22833079 | CG71: 0.21249465 | CH71: 0.12724869 | CI71: 0.083281975 | CJ71: 0.064190879 | CK71: 0.065935358 | CL71: 0.051280529 | CM71: 0.075641762 | CN71: 0.099540021 | CO71: 0.10887321 | CP71: 0.12138204 | CQ71: 0.23 | CR71: 0.25 | CS71: 0.24 | CT71: 0.25 | CU71: 0.26 | CV71: 0.26 | CW71: 0.26 | CX71: 0.08 | CY71: 0.09 | CZ71: 0.09 | DA71: 0.1 | DB71: 0.14 | DC71: 0.14 | DD71: 0.14 | DE71: 0.13 | DF71: 0.13 | DG71: 0.13 | DH71: 0.12 | DI71: 0.12 | DJ71: 0.12 | DK71: 0.14 | DL71: 0.17 | DM71: 0.17 | DN71: 0.17 | DO71: 0.17 | DP71: 0.09 | DQ71: -0.04 | DR71: -0.05 | DS71: -0.06 | DT71: -0.07 | DU71: -0.07 | DV71: -0.07 | DW71: -0.06 | DX71: -0.08 | DY71: -0.08 | DZ71: -0.08 | EA71: -0.07 | EB71: 0.12442 | EC71: 0.12674 | ED71: 0.12888 | EE71: 0.11582 | EF71: 0.11615
A72: 32416 | B72: NaN | C72: NaN | D72: -0.47840324 | E72: -0.25780741 | F72: -0.19808544 | G72: -0.21065305 | H72: -0.20287825 | I72: -0.22783304 | J72: -0.23866271 | K72: -0.21977414 | L72: -0.23104769 | M72: -0.24947498 | N72: -0.26199381 | O72: -0.15085658 | P72: -0.13035616 | Q72: -0.10449953 | R72: -0.088411704 | S72: -0.074398618 | T72: -0.15546608 | U72: -0.13863859 | V72: -0.11670506 | W72: -0.20014812 | X72: -0.090453526 | Y72: -0.16751002 | Z72: -0.029848822 | AA72: -0.034126019 | AB72: -0.13033154 | AC72: -0.12360319 | AD72: -0.0063143461 | AE72: 0.0018903974 | AF72: 0.050596658 | AG72: -0.081102807 | AH72: 0.013902457 | AI72: -0.063387445 | AJ72: 0.096720063 | AK72: -0.045472648 | AL72: -0.034532066 | AM72: 0.050155005 | AN72: 0.061494377 | AO72: -0.012408201 | AP72: 0.094998049 | AQ72: 0.00089422598 | AR72: 0.0064358117 | AS72: 0.0084180931 | AT72: 0.20660408 | AU72: 0.17099459 | AV72: 0.15686268 | AW72: 0.18869573 | AX72: 0.16475457 | AY72: 0.19771446 | AZ72: 0.18148529 | BA72: 0.15538782 | BB72: 0.14565327 | BC72: 0.16217804 | BD72: 0.11341821 | BE72: 0.083483388 | BF72: 0.13374183 | BG72: 0.13112311 | BH72: 0.089631327 | BI72: 0.17542114 | BJ72: 0.133094 | BK72: 0.20255849 | BL72: 0.17205715 | BM72: 0.20049422 | BN72: 0.20306802 | BO72: 0.1650439 | BP72: 0.13616875 | BQ72: 0.16583356 | BR72: 0.18822532 | BS72: 0.12700147 | BT72: 0.16015354 | BU72: 0.18805351 | BV72: 0.17389959 | BW72: 0.1739673 | BX72: 0.16175572 | BY72: 0.17599447 | BZ72: 0.1716108 | CA72: 0.17185445 | CB72: 0.218044 | CC72: 0.27583534 | CD72: 0.28264456 | CE72: 0.26964216 | CF72: 0.2519175 | CG72: 0.21024846 | CH72: 0.11351294 | CI72: 0.06879038 | CJ72: 0.05245635 | CK72: 0.063265759 | CL72: 0.039624226 | CM72: 0.05986988 | CN72: 0.090771711 | CO72: 0.10102039 | CP72: 0.11162369 | CQ72: 0.18 | CR72: 0.2 | CS72: 0.19 | CT72: 0.19 | CU72: 0.2 | CV72: 0.21 | CW72: 0.22 | CX72: 0.08 | CY72: 0.09 | CZ72: 0.09 | DA72: 0.09 | DB72: 0.13 | DC72: 0.13 | DD72: 0.13 | DE72: 0.13 | DF72: 0.13 | DG72: 0.12 | DH72: 0.12 | DI72: 0.12 | DJ72: 0.11 | DK72: 0.14 | DL72: 0.17 | DM72: 0.17 | DN72: 0.16 | DO72: 0.17 | DP72: 0.04 | DQ72: -0.06 | DR72: -0.08 | DS72: -0.09 | DT72: -0.09 | DU72: -0.1 | DV72: -0.1 | DW72: -0.08 | DX72: -0.11 | DY72: -0.11 | DZ72: -0.1 | EA72: -0.09 | EB72: 0.10165 | EC72: 0.10392 | ED72: 0.10585 | EE72: 0.0929 | EF72: 0.09335
A73: 32508 | B73: NaN | C73: NaN | D73: NaN | E73: -0.15818806 | F73: -0.072337433 | G73: -0.098449547 | H73: 0.097874278 | I73: 0.068751268 | J73: 0.059936331 | K73: 0.064940786 | L73: 0.049190488 | M73: 0.026961456 | N73: 0.01331058 | O73: -0.23031235 | P73: -0.204365 | Q73: -0.17443216 | R73: -0.1672197 | S73: -0.15483594 | T73: -0.1346613 | U73: -0.12302049 | V73: -0.10090531 | W73: -0.17116666 | X73: -0.076501177 | Y73: -0.12951788 | Z73: -0.076635927 | AA73: -0.091659534 | AB73: -0.085679424 | AC73: -0.074573417 | AD73: -0.032363367 | AE73: -0.037899358 | AF73: -0.037464271 | AG73: -0.040425215 | AH73: -0.022331245 | AI73: -0.016157777 | AJ73: 0.013662721 | AK73: 0.0024939528 | AL73: 0.0084243707 | AM73: 0.015179087 | AN73: 0.02841454 | AO73: 0.025629683 | AP73: 0.04395329 | AQ73: 0.037681868 | AR73: 0.040749431 | AS73: 0.04180731 | AT73: 0.040901969 | AU73: 0.056028815 | AV73: -0.014457583 | AW73: 0.026313538 | AX73: -0.010398854 | AY73: 0.018346721 | AZ73: 0.005764867 | BA73: -0.021247761 | BB73: -0.02864056 | BC73: -0.030474425 | BD73: -0.041348002 | BE73: -0.034155413 | BF73: -0.038677009 | BG73: -0.040775566 | BH73: -0.012140309 | BI73: -0.027256026 | BJ73: -0.045328428 | BK73: -0.015314138 | BL73: -0.018044194 | BM73: -0.013012439 | BN73: -0.0048325408 | BO73: -0.031770887 | BP73: -0.052784625 | BQ73: -0.041600885 | BR73: -0.026350895 | BS73: -0.057890429 | BT73: -0.033250384 | BU73: -0.016805855 | BV73: -0.024004479 | BW73: -0.028414125 | BX73: -0.026380432 | BY73: -0.029915603 | BZ73: -0.024377819 | CA73: -0.022182148 | CB73: 0.0099468653 | CC73: 0.055977216 | CD73: 0.079806393 | CE73: 0.11162451 | CF73: 0.10112692 | CG73: 0.11780701 | CH73: 0.047280586 | CI73: 0.0087168878 | CJ73: -0.0098024364 | CK73: -0.027955765 | CL73: -0.026227404 | CM73: -0.0064363938 | CN73: 0.018770304 | CO73: 0.017169308 | CP73: 0.031686691 | CQ73: 0.12 | CR73: 0.15 | CS73: 0.14 | CT73: 0.14 | CU73: 0.15 | CV73: 0.16 | CW73: 0.17 | CX73: 0.03 | CY73: 0.04 | CZ73: 0.04 | DA73: 0.04 | DB73: 0.09 | DC73: 0.09 | DD73: 0.08 | DE73: 0.08 | DF73: 0.07 | DG73: 0.07 | DH73: 0.07 | DI73: 0.06 | DJ73: 0.06 | DK73: 0.09 | DL73: 0.12 | DM73: 0.12 | DN73: 0.11 | DO73: 0.11 | DP73: 0.01 | DQ73: -0.13 | DR73: -0.14 | DS73: -0.16 | DT73: -0.16 | DU73: -0.17 | DV73: -0.17 | DW73: -0.16 | DX73: -0.18 | DY73: -0.18 | DZ73: -0.18 | EA73: -0.17 | EB73: 0.01103 | EC73: 0.01239 | ED73: 0.01317 | EE73: 0.00144 | EF73: 0.00219
A74: 32598 | B74: NaN | C74: NaN | D74: NaN | E74: NaN | F74: 0.44420642 | G74: 0.30948899 | H74: 0.047265575 | I74: -0.00083003683 | J74: -0.02958833 | K74: 0.0029921468 | L74: -0.006652255 | M74: -0.040857053 | N74: -0.064142462 | O74: 0.27741225 | P74: 0.29485433 | Q74: 0.30599273 | R74: 0.31992837 | S74: 0.32365686 | T74: 0.22075099 | U74: 0.23614189 | V74: 0.25608228 | W74: 0.070800565 | X74: 0.28827729 | Y74: 0.10816007 | Z74: 0.31576664 | AA74: 0.29050648 | AB74: 0.15188977 | AC74: 0.16318343 | AD74: 0.35213598 | AE74: 0.34880732 | AF74: 0.38368015 | AG74: 0.19468625 | AH74: 0.3468001 | AI74: 0.21848446 | AJ74: 0.40892818 | AK74: 0.23537824 | AL74: 0.24357026 | AM74: 0.38377074 | AN74: 0.39514953 | AO74: 0.26196803 | AP74: 0.4279644 | AQ74: 0.27449965 | AR74: 0.2789642 | AS74: 0.28348429 | AT74: 0.5557353 | AU74: 0.54632022 | AV74: 0.43339158 | AW74: 0.58961309 | AX74: 0.47388941 | AY74: 0.65111987 | AZ74: 0.64091299 | BA74: 0.58619545 | BB74: 0.56936056 | BC74: 0.6198796 | BD74: 0.51340401 | BE74: 0.45842744 | BF74: 0.55907669 | BG74: 0.55127333 | BH74: 0.45990374 | BI74: 0.68310371 | BJ74: 0.5474884 | BK74: 0.7348364 | BL74: 0.60998667 | BM74: 0.70654803 | BN74: 0.71746604 | BO74: 0.58227147 | BP74: 0.47954575 | BQ74: 0.50940085 | BR74: 0.60569703 | BS74: 0.42436712 | BT74: 0.53477292 | BU74: 0.58055752 | BV74: 0.56828934 | BW74: 0.56623298 | BX74: 0.52064254 | BY74: 0.56996791 | BZ74: 0.53429341 | CA74: 0.53956067 | CB74: 0.65501795 | CC74: 0.88170451 | CD74: 0.85788402 | CE74: 0.85838516 | CF74: 0.82537299 | CG74: 0.77954508 | CH74: 0.62938468 | CI74: 0.55486462 | CJ74: 0.52087295 | CK74: 0.50909189 | CL74: 0.4941925 | CM74: 0.51903155 | CN74: 0.55076347 | CO74: 0.55416978 | CP74: 0.5675906 | CQ74: 0.62 | CR74: 0.65 | CS74: 0.63 | CT74: 0.64 | CU74: 0.65 | CV74: 0.68 | CW74: 0.68 | CX74: 0.49 | CY74: 0.5 | CZ74: 0.5 | DA74: 0.5 | DB74: 0.57 | DC74: 0.56 | DD74: 0.56 | DE74: 0.55 | DF74: 0.54 | DG74: 0.54 | DH74: 0.53 | DI74: 0.52 | DJ74: 0.51 | DK74: 0.54 | DL74: 0.59 | DM74: 0.59 | DN74: 0.58 | DO74: 0.58 | DP74: 0.4 | DQ74: 0.21 | DR74: 0.18 | DS74: 0.16 | DT74: 0.15 | DU74: 0.14 | DV74: 0.14 | DW74: 0.15 | DX74: 0.11 | DY74: 0.11 | DZ74: 0.11 | EA74: 0.13 | EB74: 0.49431 | EC74: 0.4969 | ED74: 0.49763 | EE74: 0.47567 | EF74: 0.47639
A75: 32689 | B75: NaN | C75: NaN | D75: NaN | E75: NaN | F75: NaN | G75: 0.078760839 | H75: 0.25224875 | I75: 0.19206332 | J75: 0.16711972 | K75: 0.095759212 | L75: 0.078395338 | M75: 0.04562651 | N75: 0.032576992 | O75: -0.15548347 | P75: -0.12374953 | Q75: -0.096249569 | R75: -0.079210949 | S75: -0.061882961 | T75: 0.13614053 | U75: 0.13930734 | V75: 0.15991102 | W75: -0.06535328 | X75: 0.18403518 | Y75: -0.028201472 | Z75: 0.1757783 | AA75: 0.065498349 | AB75: 0.014874819 | AC75: 0.024410892 | AD75: 0.24383037 | AE75: 0.23958302 | AF75: 0.15811704 | AG75: 0.061573645 | AH75: 0.2523411 | AI75: 0.080209257 | AJ75: 0.21080201 | AK75: 0.099009561 | AL75: 0.10844249 | AM75: 0.30313561 | AN75: 0.31945151 | AO75: 0.12872471 | AP75: 0.28248767 | AQ75: 0.14156702 | AR75: 0.1470139 | AS75: 0.15085045 | AT75: 0.18562592 | AU75: 0.24824345 | AV75: 0.12543646 | AW75: 0.19475081 | AX75: 0.1308017 | AY75: 0.13700762 | AZ75: 0.11769934 | BA75: 0.089355348 | BB75: 0.14459045 | BC75: 0.10102679 | BD75: 0.13928586 | BE75: 0.17823453 | BF75: 0.14672929 | BG75: 0.14326591 | BH75: 0.23714031 | BI75: 0.080876684 | BJ75: 0.12357632 | BK75: 0.098663155 | BL75: 0.1555814 | BM75: 0.10089675 | BN75: 0.10750966 | BO75: 0.092801558 | BP75: 0.078040747 | BQ75: 0.098105764 | BR75: 0.13800917 | BS75: 0.079951584 | BT75: 0.096831692 | BU75: 0.17007463 | BV75: 0.11276371 | BW75: 0.14370947 | BX75: 0.099474744 | BY75: 0.12261739 | BZ75: 0.10490568 | CA75: 0.10683045 | CB75: 0.18461683 | CC75: 0.17749934 | CD75: 0.2452837 | CE75: 0.23426325 | CF75: 0.21294362 | CG75: 0.25761065 | CH75: 0.1681992 | CI75: 0.12351018 | CJ75: 0.11403901 | CK75: 0.17397804 | CL75: 0.095158014 | CM75: 0.11117612 | CN75: 0.18880173 | CO75: 0.21634509 | CP75: 0.2292241 | CQ75: 0.21 | CR75: 0.24 | CS75: 0.23 | CT75: 0.23 | CU75: 0.24 | CV75: 0.25 | CW75: 0.25 | CX75: 0.16 | CY75: 0.17 | CZ75: 0.17 | DA75: 0.18 | DB75: 0.22 | DC75: 0.22 | DD75: 0.22 | DE75: 0.21 | DF75: 0.21 | DG75: 0.21 | DH75: 0.2 | DI75: 0.2 | DJ75: 0.19 | DK75: 0.22 | DL75: 0.25 | DM75: 0.25 | DN75: 0.25 | DO75: 0.25 | DP75: 0.12 | DQ75: 0.03 | DR75: 0.02 | DS75: 0.01 | DT75: 0 | DU75: 0 | DV75: 0 | DW75: 0 | DX75: -0.02 | DY75: -0.03 | DZ75: -0.03 | EA75: -0.01 | EB75: 0.14363 | EC75: 0.14437 | ED75: 0.14457 | EE75: 0.13385 | EF75: 0.13596
A76: 32781 | B76: NaN | C76: NaN | D76: NaN | E76: NaN | F76: NaN | G76: NaN | H76: 0.27285412 | I76: 0.068342565 | J76: 0.026333157 | K76: -0.030093156 | L76: -0.05365133 | M76: -0.093878926 | N76: -0.11615683 | O76: -0.22116163 | P76: -0.14714328 | Q76: -0.11822825 | R76: -0.10482108 | S76: -0.089964456 | T76: 0.12377962 | U76: 0.14060878 | V76: 0.16708503 | W76: -0.12902044 | X76: 0.18471232 | Y76: -0.087363819 | Z76: 0.17704219 | AA76: 0.035236049 | AB76: -0.039995967 | AC76: -0.027398485 | AD76: 0.25737552 | AE76: 0.24834432 | AF76: 0.15989923 | AG76: 0.0059262523 | AH76: 0.24826317 | AI76: 0.029858182 | AJ76: 0.20729808 | AK76: 0.049040717 | AL76: 0.056352881 | AM76: 0.29184908 | AN76: 0.30715054 | AO76: 0.074992622 | AP76: 0.26902629 | AQ76: 0.087101268 | AR76: 0.091678117 | AS76: 0.095976634 | AT76: 0.29009199 | AU76: 0.26669674 | AV76: 0.23914716 | AW76: 0.25826305 | AX76: 0.23828673 | AY76: 0.206172 | AZ76: 0.18362427 | BA76: 0.15897799 | BB76: 0.19270717 | BC76: 0.16480039 | BD76: 0.18988774 | BE76: 0.2106761 | BF76: 0.19892469 | BG76: 0.19550738 | BH76: 0.24730544 | BI76: 0.12236743 | BJ76: 0.17623613 | BK76: 0.13123806 | BL76: 0.20777082 | BM76: 0.14482574 | BN76: 0.1522962 | BO76: 0.1710337 | BP76: 0.17411349 | BQ76: 0.20144128 | BR76: 0.20162789 | BS76: 0.18702704 | BT76: 0.17903346 | BU76: 0.23082182 | BV76: 0.1922133 | BW76: 0.20199282 | BX76: 0.19002056 | BY76: 0.18772248 | BZ76: 0.19399771 | CA76: 0.19309895 | CB76: 0.23476904 | CC76: 0.20811935 | CD76: 0.26850751 | CE76: 0.28706753 | CF76: 0.27494136 | CG76: 0.27989782 | CH76: 0.23833603 | CI76: 0.20413587 | CJ76: 0.19327898 | CK76: 0.19245608 | CL76: 0.19156682 | CM76: 0.20190268 | CN76: 0.20883041 | CO76: 0.22850734 | CP76: 0.23972899 | CQ76: 0.16 | CR76: 0.19 | CS76: 0.18 | CT76: 0.18 | CU76: 0.19 | CV76: 0.2 | CW76: 0.2 | CX76: 0.18 | CY76: 0.19 | CZ76: 0.19 | DA76: 0.19 | DB76: 0.23 | DC76: 0.23 | DD76: 0.23 | DE76: 0.22 | DF76: 0.22 | DG76: 0.22 | DH76: 0.22 | DI76: 0.21 | DJ76: 0.2 | DK76: 0.23 | DL76: 0.25 | DM76: 0.25 | DN76: 0.25 | DO76: 0.25 | DP76: 0.18 | DQ76: 0.11 | DR76: 0.09 | DS76: 0.08 | DT76: 0.08 | DU76: 0.07 | DV76: 0.07 | DW76: 0.08 | DX76: 0.05 | DY76: 0.05 | DZ76: 0.05 | EA76: 0.06 | EB76: 0.23542 | EC76: 0.23661 | ED76: 0.23712 | EE76: 0.22959 | EF76: 0.2312
